Workbook
Name List_categst: #REF!
Name List_days: #REF!
Name list_io: #REF!
Name List_months: #REF!
Name List_Year: #REF!

Sheet Read me first
B5: Timesheet
A10: 1. Why fill in the timesheet?
A11: The timesheet is a documentation instrument for all those working with the development of the intellectual outputs. The timesheets completed during the duration of the project must be keept by the beneficiary organisation and presented upon request to the National Agency granting the project or or other control abilitated EU bodies and third parts.
A16: 2. When should you fill in the timesheet?
A17: The timesheet must be filled in monthly by each of the persons working on the project activities.
A21: 3. Who should fill in the timesheet?
A22: All persons working part of your organization working on the project must fill in the timesheet. Based on the programme guide and the project application, those working are included in one of the next categories of staff: Senior Lecturer, professor, junior Lecturer, research assistant, technician, administrative
A27: 4. How to use this template?
A28: The template is composed of the next: - Summary page - Page for each month of the year - Drop down list. Those filling in the timesheets should fill the pages relevant for the months in which they have worked. Each individual page should be filled with the next information: name of the person, organisation, category of staff. In the table below it is possible to select Work package from a drop down list. All this informations will be summarised both on the page in work as well as on the summary page.

Sheet Summary
C4: Timesheet for project outputs
A8: Project name | B8: GREATER – Growing Rwanda Energy Awareness Through highER education
A9: Project ID | B9: 101083081 ERASMUS-EDU-2022-CBHE
A11: Name | B11: HIRWA Jean Luc
A12: Organisation | B12: RP - RWANDA POLYTECHNIC
A13: Category of staff | B13: Teachers/Trainers/Researchers
B14: WP1 | C14: WP2 | D14: WP3 | E14: WP4 | F14: WP5 | G14: WP6 | H14: WP7
A16: January 2023 | B16: =SUMIFS(January23!$K$4:$K$8,January23!$J$4:$J$8,Summary!B$14) -> 0 | C16: =SUMIFS(January23!$K$4:$K$8,January23!$J$4:$J$8,Summary!C$14) -> 0 | D16: =SUMIFS(January23!$K$4:$K$8,January23!$J$4:$J$8,Summary!D$14) -> 0 | E16: =SUMIFS(January23!$K$4:$K$8,January23!$J$4:$J$8,Summary!E$14) -> 0 | F16: =SUMIFS(January23!$K$4:$K$8,January23!$J$4:$J$8,Summary!F$14) -> 5 | G16: =SUMIFS(January23!$K$4:$K$8,January23!$J$4:$J$8,Summary!G$14) -> 0 | H16: =SUMIFS(January23!$K$4:$K$8,January23!$J$4:$J$8,Summary!H$14) -> 0
A17: February 2023 | B17: =SUMIFS(February23!$K$4:$K$13,February23!$J$4:$J$13,Summary!B$14) -> 0 | C17: =SUMIFS(February23!$K$4:$K$13,February23!$J$4:$J$13,Summary!C$14) -> 0 | D17: =SUMIFS(February23!$K$4:$K$13,February23!$J$4:$J$13,Summary!D$14) -> 0 | E17: =SUMIFS(February23!$K$4:$K$13,February23!$J$4:$J$13,Summary!E$14) -> 0 | F17: =SUMIFS(February23!$K$4:$K$13,February23!$J$4:$J$13,Summary!F$14) -> 0 | G17: =SUMIFS(February23!$K$4:$K$13,February23!$J$4:$J$13,Summary!G$14) -> 0 | H17: =SUMIFS(February23!$K$4:$K$13,February23!$J$4:$J$13,Summary!H$14) -> 0
A18: March 2023 | B18: =SUMIFS(March23!$K$4:$K$13,March23!$J$4:$J$13,Summary!B$14) -> 0 | C18: =SUMIFS(March23!$K$4:$K$13,March23!$J$4:$J$13,Summary!C$14) -> 0 | D18: =SUMIFS(March23!$K$4:$K$13,March23!$J$4:$J$13,Summary!D$14) -> 0 | E18: =SUMIFS(March23!$K$4:$K$13,March23!$J$4:$J$13,Summary!E$14) -> 0 | F18: =SUMIFS(March23!$K$4:$K$13,March23!$J$4:$J$13,Summary!F$14) -> 0 | G18: =SUMIFS(March23!$K$4:$K$13,March23!$J$4:$J$13,Summary!G$14) -> 0 | H18: =SUMIFS(March23!$K$4:$K$13,March23!$J$4:$J$13,Summary!H$14) -> 0
A19: April 2023 | B19: =SUMIFS(April23!$K$4:$K$13,April23!$J$4:$J$13,Summary!B$14) -> 0 | C19: =SUMIFS(April23!$K$4:$K$13,April23!$J$4:$J$13,Summary!C$14) -> 0 | D19: =SUMIFS(April23!$K$4:$K$13,April23!$J$4:$J$13,Summary!D$14) -> 0 | E19: =SUMIFS(April23!$K$4:$K$13,April23!$J$4:$J$13,Summary!E$14) -> 0 | F19: =SUMIFS(April23!$K$4:$K$13,April23!$J$4:$J$13,Summary!F$14) -> 0 | G19: =SUMIFS(April23!$K$4:$K$13,April23!$J$4:$J$13,Summary!G$14) -> 0 | H19: =SUMIFS(April23!$K$4:$K$13,April23!$J$4:$J$13,Summary!H$14) -> 0
A20: May 2023 | B20: =SUMIFS('May23'!$K$4:$K$13,'May23'!$J$4:$J$13,Summary!B$14) -> 0 | C20: =SUMIFS('May23'!$K$4:$K$13,'May23'!$J$4:$J$13,Summary!C$14) -> 0 | D20: =SUMIFS('May23'!$K$4:$K$13,'May23'!$J$4:$J$13,Summary!D$14) -> 0 | E20: =SUMIFS('May23'!$K$4:$K$13,'May23'!$J$4:$J$13,Summary!E$14) -> 0 | F20: =SUMIFS('May23'!$K$4:$K$13,'May23'!$J$4:$J$13,Summary!F$14) -> 0 | G20: =SUMIFS('May23'!$K$4:$K$13,'May23'!$J$4:$J$13,Summary!G$14) -> 0 | H20: =SUMIFS('May23'!$K$4:$K$13,'May23'!$J$4:$J$13,Summary!H$14) -> 0
A21: June 2023 | B21: =SUMIFS(June23!$K$4:$K$13,June23!$J$4:$J$13,Summary!B$14) -> 0 | C21: =SUMIFS(June23!$K$4:$K$13,June23!$J$4:$J$13,Summary!C$14) -> 0 | D21: =SUMIFS(June23!$K$4:$K$13,June23!$J$4:$J$13,Summary!D$14) -> 0 | E21: =SUMIFS(June23!$K$4:$K$13,June23!$J$4:$J$13,Summary!E$14) -> 0 | F21: =SUMIFS(June23!$K$4:$K$13,June23!$J$4:$J$13,Summary!F$14) -> 0 | G21: =SUMIFS(June23!$K$4:$K$13,June23!$J$4:$J$13,Summary!G$14) -> 0 | H21: =SUMIFS(June23!$K$4:$K$13,June23!$J$4:$J$13,Summary!H$14) -> 0
A22: July 2023 | B22: =SUMIFS(July23!$K$4:$K$13,July23!$J$4:$J$13,Summary!B$14) -> 0 | C22: =SUMIFS(July23!$K$4:$K$13,July23!$J$4:$J$13,Summary!C$14) -> 0 | D22: =SUMIFS(July23!$K$4:$K$13,July23!$J$4:$J$13,Summary!D$14) -> 0 | E22: =SUMIFS(July23!$K$4:$K$13,July23!$J$4:$J$13,Summary!E$14) -> 0 | F22: =SUMIFS(July23!$K$4:$K$13,July23!$J$4:$J$13,Summary!F$14) -> 0 | G22: =SUMIFS(July23!$K$4:$K$13,July23!$J$4:$J$13,Summary!G$14) -> 0 | H22: =SUMIFS(July23!$K$4:$K$13,July23!$J$4:$J$13,Summary!H$14) -> 0
A23: August 2023 | B23: =SUMIFS(August23!$K$4:$K$13,August23!$J$4:$J$13,Summary!B$14) -> 0 | C23: =SUMIFS(August23!$K$4:$K$13,August23!$J$4:$J$13,Summary!C$14) -> 0 | D23: =SUMIFS(August23!$K$4:$K$13,August23!$J$4:$J$13,Summary!D$14) -> 0 | E23: =SUMIFS(August23!$K$4:$K$13,August23!$J$4:$J$13,Summary!E$14) -> 0 | F23: =SUMIFS(August23!$K$4:$K$13,August23!$J$4:$J$13,Summary!F$14) -> 0 | G23: =SUMIFS(August23!$K$4:$K$13,August23!$J$4:$J$13,Summary!G$14) -> 0 | H23: =SUMIFS(August23!$K$4:$K$13,August23!$J$4:$J$13,Summary!H$14) -> 0
A24: September 2023 | B24: =SUMIFS(September23!$K$4:$K$13,September23!$J$4:$J$13,Summary!B$14) -> 0 | C24: =SUMIFS(September23!$K$4:$K$13,September23!$J$4:$J$13,Summary!C$14) -> 0 | D24: =SUMIFS(September23!$K$4:$K$13,September23!$J$4:$J$13,Summary!D$14) -> 0 | E24: =SUMIFS(September23!$K$4:$K$13,September23!$J$4:$J$13,Summary!E$14) -> 0 | F24: =SUMIFS(September23!$K$4:$K$13,September23!$J$4:$J$13,Summary!F$14) -> 0 | G24: =SUMIFS(September23!$K$4:$K$13,September23!$J$4:$J$13,Summary!G$14) -> 0 | H24: =SUMIFS(September23!$K$4:$K$13,September23!$J$4:$J$13,Summary!H$14) -> 0
A25: October 2023 | B25: =SUMIFS(October23!$K$4:$K$13,October23!$J$4:$J$13,Summary!B$14) -> 0 | C25: =SUMIFS(October23!$K$4:$K$13,October23!$J$4:$J$13,Summary!C$14) -> 0 | D25: =SUMIFS(October23!$K$4:$K$13,October23!$J$4:$J$13,Summary!D$14) -> 0 | E25: =SUMIFS(October23!$K$4:$K$13,October23!$J$4:$J$13,Summary!E$14) -> 0 | F25: =SUMIFS(October23!$K$4:$K$13,October23!$J$4:$J$13,Summary!F$14) -> 0 | G25: =SUMIFS(October23!$K$4:$K$13,October23!$J$4:$J$13,Summary!G$14) -> 0 | H25: =SUMIFS(October23!$K$4:$K$13,October23!$J$4:$J$13,Summary!H$14) -> 0
A26: November 2023 | B26: =SUMIFS(November23!$K$4:$K$13,November23!$J$4:$J$13,Summary!B$14) -> 0 | C26: =SUMIFS(November23!$K$4:$K$13,November23!$J$4:$J$13,Summary!C$14) -> 0 | D26: =SUMIFS(November23!$K$4:$K$13,November23!$J$4:$J$13,Summary!D$14) -> 0 | E26: =SUMIFS(November23!$K$4:$K$13,November23!$J$4:$J$13,Summary!E$14) -> 0 | F26: =SUMIFS(November23!$K$4:$K$13,November23!$J$4:$J$13,Summary!F$14) -> 0 | G26: =SUMIFS(November23!$K$4:$K$13,November23!$J$4:$J$13,Summary!G$14) -> 0 | H26: =SUMIFS(November23!$K$4:$K$13,November23!$J$4:$J$13,Summary!H$14) -> 0
A27: December 2023 | B27: =SUMIFS(December23!$K$4:$K$13,December23!$J$4:$J$13,Summary!B$14) -> 0 | C27: =SUMIFS(December23!$K$4:$K$13,December23!$J$4:$J$13,Summary!C$14) -> 0 | D27: =SUMIFS(December23!$K$4:$K$13,December23!$J$4:$J$13,Summary!D$14) -> 0 | E27: =SUMIFS(December23!$K$4:$K$13,December23!$J$4:$J$13,Summary!E$14) -> 0 | F27: =SUMIFS(December23!$K$4:$K$13,December23!$J$4:$J$13,Summary!F$14) -> 0 | G27: =SUMIFS(December23!$K$4:$K$13,December23!$J$4:$J$13,Summary!G$14) -> 0 | H27: =SUMIFS(December23!$K$4:$K$13,December23!$J$4:$J$13,Summary!H$14) -> 0
A28: January 2024 | B28: =SUMIFS(January24!$K$4:$K$8,January24!$J$4:$J$8,Summary!B$14) -> 3 | C28: =SUMIFS(January24!$K$4:$K$8,January24!$J$4:$J$8,Summary!C$14) -> 0 | D28: =SUMIFS(January24!$K$4:$K$8,January24!$J$4:$J$8,Summary!D$14) -> 0 | E28: =SUMIFS(January24!$K$4:$K$8,January24!$J$4:$J$8,Summary!E$14) -> 0 | F28: =SUMIFS(January24!$K$4:$K$8,January24!$J$4:$J$8,Summary!F$14) -> 0 | G28: =SUMIFS(January24!$K$4:$K$8,January24!$J$4:$J$8,Summary!G$14) -> 0 | H28: =SUMIFS(January24!$K$4:$K$8,January24!$J$4:$J$8,Summary!H$14) -> 0
A29: February 2024 | B29: =SUMIFS(February24!$K$4:$K$13,February24!$J$4:$J$13,Summary!B$14) -> 0 | C29: =SUMIFS(February24!$K$4:$K$13,February24!$J$4:$J$13,Summary!C$14) -> 0 | D29: =SUMIFS(February24!$K$4:$K$13,February24!$J$4:$J$13,Summary!D$14) -> 0 | E29: =SUMIFS(February24!$K$4:$K$13,February24!$J$4:$J$13,Summary!E$14) -> 0 | F29: =SUMIFS(February24!$K$4:$K$13,February24!$J$4:$J$13,Summary!F$14) -> 0 | G29: =SUMIFS(February24!$K$4:$K$13,February24!$J$4:$J$13,Summary!G$14) -> 0 | H29: =SUMIFS(February24!$K$4:$K$13,February24!$J$4:$J$13,Summary!H$14) -> 0
A30: March 2024 | B30: =SUMIFS(March24!$K$4:$K$13,March24!$J$4:$J$13,Summary!B$14) -> 0 | C30: =SUMIFS(March24!$K$4:$K$13,March24!$J$4:$J$13,Summary!C$14) -> 0 | D30: =SUMIFS(March24!$K$4:$K$13,March24!$J$4:$J$13,Summary!D$14) -> 0 | E30: =SUMIFS(March24!$K$4:$K$13,March24!$J$4:$J$13,Summary!E$14) -> 0 | F30: =SUMIFS(March24!$K$4:$K$13,March24!$J$4:$J$13,Summary!F$14) -> 0 | G30: =SUMIFS(March24!$K$4:$K$13,March24!$J$4:$J$13,Summary!G$14) -> 0 | H30: =SUMIFS(March24!$K$4:$K$13,March24!$J$4:$J$13,Summary!H$14) -> 0
A31: April 2024 | B31: =SUMIFS(April24!$K$4:$K$13,April24!$J$4:$J$13,Summary!B$14) -> 0 | C31: =SUMIFS(April24!$K$4:$K$13,April24!$J$4:$J$13,Summary!C$14) -> 0 | D31: =SUMIFS(April24!$K$4:$K$13,April24!$J$4:$J$13,Summary!D$14) -> 0 | E31: =SUMIFS(April24!$K$4:$K$13,April24!$J$4:$J$13,Summary!E$14) -> 0 | F31: =SUMIFS(April24!$K$4:$K$13,April24!$J$4:$J$13,Summary!F$14) -> 0 | G31: =SUMIFS(April24!$K$4:$K$13,April24!$J$4:$J$13,Summary!G$14) -> 0 | H31: =SUMIFS(April24!$K$4:$K$13,April24!$J$4:$J$13,Summary!H$14) -> 0
A32: May 2024 | B32: =SUMIFS('May24'!$K$4:$K$13,'May24'!$J$4:$J$13,Summary!B$14) -> 0 | C32: =SUMIFS('May24'!$K$4:$K$13,'May24'!$J$4:$J$13,Summary!C$14) -> 0 | D32: =SUMIFS('May24'!$K$4:$K$13,'May24'!$J$4:$J$13,Summary!D$14) -> 0 | E32: =SUMIFS('May24'!$K$4:$K$13,'May24'!$J$4:$J$13,Summary!E$14) -> 0 | F32: =SUMIFS('May24'!$K$4:$K$13,'May24'!$J$4:$J$13,Summary!F$14) -> 0 | G32: =SUMIFS('May24'!$K$4:$K$13,'May24'!$J$4:$J$13,Summary!G$14) -> 0 | H32: =SUMIFS('May24'!$K$4:$K$13,'May24'!$J$4:$J$13,Summary!H$14) -> 0
A33: June 2024 | B33: =SUMIFS(June24!$K$4:$K$13,June24!$J$4:$J$13,Summary!B$14) -> 0 | C33: =SUMIFS(June24!$K$4:$K$13,June24!$J$4:$J$13,Summary!C$14) -> 0 | D33: =SUMIFS(June24!$K$4:$K$13,June24!$J$4:$J$13,Summary!D$14) -> 0 | E33: =SUMIFS(June24!$K$4:$K$13,June24!$J$4:$J$13,Summary!E$14) -> 0 | F33: =SUMIFS(June24!$K$4:$K$13,June24!$J$4:$J$13,Summary!F$14) -> 0 | G33: =SUMIFS(June24!$K$4:$K$13,June24!$J$4:$J$13,Summary!G$14) -> 0 | H33: =SUMIFS(June24!$K$4:$K$13,June24!$J$4:$J$13,Summary!H$14) -> 0
A34: Total hours | B34: =SUM(B16:B33) -> 3 | C34: =SUM(C16:C33) -> 0 | D34: =SUM(D16:D33) -> 0 | E34: =SUM(E16:E33) -> 0 | F34: =SUM(F16:F33) -> 5 | G34: =SUM(G16:G33) -> 0 | H34: =SUM(H16:H33) -> 0
A35: Total days | B35: =B34/'Drop-down lists'!$D$21 -> 0.375 | C35: =C34/'Drop-down lists'!$D$21 -> 0 | D35: =D34/'Drop-down lists'!$D$21 -> 0 | E35: =E34/'Drop-down lists'!$D$21 -> 0 | F35: =F34/'Drop-down lists'!$D$21 -> 0.625 | G35: =G34/'Drop-down lists'!$D$21 -> 0 | H35: =H34/'Drop-down lists'!$D$21 -> 0

Sheet timesheet
J2: Summary
J3: Work Package | K3: Hours
A4: Project name | C4: =Summary!B8 -> GREATER – Growing Rwanda Energy Awareness Through highER education | J4: WP1 - Management and coordination | K4: =SUMIFS($A$13:$A$52,$C$13:$C$52,$J4) -> 36
J5: WP2 - Collaboration design | K5: =SUMIFS($A$13:$A$52,$C$13:$C$52,$J5) -> 1
A6: Project ID | C6: =Summary!B9 -> 101083081 ERASMUS-EDU-2022-CBHE | J6: WP3 - Infrastructures | K6: =SUMIFS($A$13:$A$52,$C$13:$C$52,$J6) -> 24
A7: Employee | C7: HIRWA Jean Luc | J7: WP4 - Curricula design | K7: =SUMIFS($A$13:$A$52,$C$13:$C$52,$J7) -> 5
A8: Organization | C8: RP - RWANDA POLYTECHNIC | J8: WP5 - Training and coaching | K8: =SUMIFS($A$13:$A$52,$C$13:$C$52,$J8) -> 45
A9: Staff category | C9: Junior Lecturer / Research assistant | J9: WP6 - Transfer methodologies | K9: =SUMIFS($A$13:$A$52,$C$13:$C$52,$J9) -> 5
J10: WP7 - Impact and dissemination | K10: =SUMIFS($A$13:$A$52,$C$13:$C$52,$J10) -> 54
A12: Total number of hours | B12: Date (dd/mm/yyyy) | C12: Work Package | D12: Comments
A13: 2 | B13: 44963 | C13: WP7 - Impact and dissemination | D13: Attended the official launch and kick-off meeting of the GREATER at INES Ruhengeri
A14: 5 | B14: 44964 | C14: WP5 - Training and coaching | D14: Attended the workshop day 1 @INES
A15: 5 | B15: 44965 | C15: WP5 - Training and coaching | D15: Attended the workshop day 2 @INES
A16: 1 | B16: 44966 | C16: WP1 - Management and coordination | D16: Visit the RP facilities
A17: 2 | B17: 45001 | C17: WP1 - Management and coordination | D17: Attended a Steering Committee Meeting
A18: 2 | B18: 45033 | C18: WP1 - Management and coordination | D18: Attended a team meeting at RP Tumba
A19: 2 | B19: 45036 | C19: WP1 - Management and coordination | D19: Attended a Steering Committee Meeting
A20: 1 | B20: 45070 | C20: WP1 - Management and coordination | D20: Planning a workshop on identification and design of our Living Lab requirements
A21: 8 | B21: 45090 | C21: WP3 - Infrastructures | D21: Workshop on identification and design of our Living Lab requirements
A22: 8 | B22: 45091 | C22: WP3 - Infrastructures | D22: Workshop on identification and design of our Living Lab requirements
A23: 8 | B23: 45092 | C23: WP3 - Infrastructures | D23: Workshop on identification and design of our Living Lab requirements
A24: 3 | B24: 45167 | C24: WP1 - Management and coordination | D24: Attended General Assembly/Launch of the GREATER Project @UR
... A36: 5 | B36: 45362 | C36: WP7 - Impact and dissemination | D36: Developing Project's Website
A37: 5 | B37: 16/04/2024 | C37: WP5 - Training and coaching | D37: Attended Workshop day 1 @HBRS
A38: 5 | B38: 17/04/2024 | C38: WP5 - Training and coaching | D38: Attended Workshop day 1 @HBRS
A39: 5 | B39: 18/04/2024 | C39: WP5 - Training and coaching | D39: Attended Workshop day 1 @HBRS
A40: 5 | B40: 19/04/2024 | C40: WP5 - Training and coaching | D40: Attended Workshop day 1 @HBRS
A41: 5 | B41: 22/04/2024 | C41: WP5 - Training and coaching | D41: Attended Workshop day 1 @HN
A42: 5 | B42: 23/04/2024 | C42: WP5 - Training and coaching | D42: Attended Workshop day 2 @HN
A43: 5 | B43: 24/04/2024 | C43: WP5 - Training and coaching | D43: Attended Workshop day 3 @HN
A44: 5 | B44: 45413 | C44: WP1 - Management and coordination | D44: Report of attended workshop in Germany mobility
A45: 5 | B45: 45418 | C45: WP1 - Management and coordination | D45: Report of attended workshop in Germany mobility
A46: 2 | B46: 45440 | C46: WP1 - Management and coordination | D46: Attended a Steering Committee Meeting
A47: 2 | B47: 45449 | C47: WP1 - Management and coordination | D47: Local Coordination Meeting about the progress of the project
A48: 4 | B48: 45517 | C48: WP7 - Impact and dissemination | D48: Developing FMS
A49: 4 | B49: 45518 | C49: WP7 - Impact and dissemination | D49: Developing FMS
A50: 4 | B50: 45519 | C50: WP7 - Impact and dissemination | D50: Developing FMS
A51: 4 | B51: 45520 | C51: WP7 - Impact and dissemination | D51: Developing FMS
A52: 1 | B52: 45525 | C52: WP1 - Management and coordination | D52: Collection of Financial Documents and Check Ups
A53: =SUM(A13:A52) -> 170
...

Sheet January23
A2: Project name | C2: =Summary!B8 -> GREATER – Growing Rwanda Energy Awareness Through highER education | J2: Summary
J3: Work Package | K3: Hours
A4: Project ID | C4: =Summary!B9 -> 101083081 ERASMUS-EDU-2022-CBHE | J4: WP1 | K4: =SUMIFS($A$13:$A$34,$C$13:$C$34,$J4) -> 0
A5: Month | C5: January | J5: WP2 | K5: =SUMIFS($A$13:$A$34,$C$13:$C$34,$J5) -> 0
A6: Year | C6: 2023 | J6: WP3 | K6: =SUMIFS($A$13:$A$34,$C$13:$C$34,$J6) -> 0
A7: Employee | J7: WP4 | K7: =SUMIFS($A$13:$A$34,$C$13:$C$34,$J7) -> 0
A8: Organization | J8: WP5 | K8: =SUMIFS($A$13:$A$34,$C$13:$C$34,$J8) -> 5
A9: Staff category | J9: WP6 | K9: =SUMIFS($A$13:$A$34,$C$13:$C$34,$J9) -> 0
J10: WP7 | K10: =SUMIFS($A$13:$A$34,$C$13:$C$34,$J10) -> 0
A12: Total number of hours | B12: Day | C12: Work Package | D12: Comments
A13: 5 | B13: 11 | C13: WP5
A35: =SUM(A13:A34) -> 5
B36: Date | G36: Signature of the staff member | L36: Signature of the person responsbile in the institution

Sheet February23
A2: Project name | C2: =Summary!B8 -> GREATER – Growing Rwanda Energy Awareness Through highER education | J2: Summary
J3: Work Package | K3: Hours
A4: Project ID | C4: =Summary!B9 -> 101083081 ERASMUS-EDU-2022-CBHE | J4: WP1 | K4: =SUMIFS($A$13:$A$34,$C$13:$C$34,$J4) -> 0
A5: Month | C5: February | J5: WP2 | K5: =SUMIFS($A$13:$A$34,$C$13:$C$34,$J5) -> 0
A6: Year | C6: 2023 | J6: WP3 | K6: =SUMIFS($A$13:$A$34,$C$13:$C$34,$J6) -> 0
A7: Employee | J7: WP4 | K7: =SUMIFS($A$13:$A$34,$C$13:$C$34,$J7) -> 0
A8: Organization | J8: WP5 | K8: =SUMIFS($A$13:$A$34,$C$13:$C$34,$J8) -> 0
A9: Staff category | J9: WP6 | K9: =SUMIFS($A$13:$A$34,$C$13:$C$34,$J9) -> 0
J10: WP7 | K10: =SUMIFS($A$13:$A$34,$C$13:$C$34,$J10) -> 0
A12: Total number of hours | B12: Day | C12: Work Package | D12: Comments
A35: =SUM(A13:A34) -> 0
B36: Date | G36: Signature of the staff member | L36: Signature of the person responsbile in the institution

Sheet March23
A2: Project name | C2: =Summary!B8 -> GREATER – Growing Rwanda Energy Awareness Through highER education | J2: Summary
J3: Work Package | K3: Hours
A4: Project ID | C4: =Summary!B9 -> 101083081 ERASMUS-EDU-2022-CBHE | J4: WP1 | K4: =SUMIFS($A$13:$A$34,$C$13:$C$34,$J4) -> 0
A5: Month | C5: March | J5: WP2 | K5: =SUMIFS($A$13:$A$34,$C$13:$C$34,$J5) -> 0
A6: Year | C6: 2023 | J6: WP3 | K6: =SUMIFS($A$13:$A$34,$C$13:$C$34,$J6) -> 0
A7: Employee | J7: WP4 | K7: =SUMIFS($A$13:$A$34,$C$13:$C$34,$J7) -> 0
A8: Organization | J8: WP5 | K8: =SUMIFS($A$13:$A$34,$C$13:$C$34,$J8) -> 0
A9: Staff category | J9: WP6 | K9: =SUMIFS($A$13:$A$34,$C$13:$C$34,$J9) -> 0
J10: WP7 | K10: =SUMIFS($A$13:$A$34,$C$13:$C$34,$J10) -> 0
A12: Total number of hours | B12: Day | C12: Work Package | D12: Comments
A35: =SUM(A13:A34) -> 0
B36: Date | G36: Signature of the staff member | L36: Signature of the person responsbile in the institution

Sheet April23
A2: Project name | C2: =Summary!B8 -> GREATER – Growing Rwanda Energy Awareness Through highER education | J2: Summary
J3: Work Package | K3: Hours
A4: Project ID | C4: =Summary!B9 -> 101083081 ERASMUS-EDU-2022-CBHE | J4: WP1 | K4: =SUMIFS($A$13:$A$34,$C$13:$C$34,$J4) -> 0
A5: Month | C5: April | J5: WP2 | K5: =SUMIFS($A$13:$A$34,$C$13:$C$34,$J5) -> 0
A6: Year | C6: 2023 | J6: WP3 | K6: =SUMIFS($A$13:$A$34,$C$13:$C$34,$J6) -> 0
A7: Employee | J7: WP4 | K7: =SUMIFS($A$13:$A$34,$C$13:$C$34,$J7) -> 0
A8: Organization | J8: WP5 | K8: =SUMIFS($A$13:$A$34,$C$13:$C$34,$J8) -> 0
A9: Staff category | J9: WP6 | K9: =SUMIFS($A$13:$A$34,$C$13:$C$34,$J9) -> 0
J10: WP7 | K10: =SUMIFS($A$13:$A$34,$C$13:$C$34,$J10) -> 0
A12: Total number of hours | B12: Day | C12: Work Package | D12: Comments
A35: =SUM(A13:A34) -> 0
B36: Date | G36: Signature of the staff member | L36: Signature of the person responsbile in the institution

Sheet May23
A2: Project name | C2: =Summary!B8 -> GREATER – Growing Rwanda Energy Awareness Through highER education | J2: Summary
J3: Work Package | K3: Hours
A4: Project ID | C4: =Summary!B9 -> 101083081 ERASMUS-EDU-2022-CBHE | J4: WP1 | K4: =SUMIFS($A$13:$A$34,$C$13:$C$34,$J4) -> 0
A5: Month | C5: May | J5: WP2 | K5: =SUMIFS($A$13:$A$34,$C$13:$C$34,$J5) -> 0
A6: Year | C6: 2023 | J6: WP3 | K6: =SUMIFS($A$13:$A$34,$C$13:$C$34,$J6) -> 0
A7: Employee | J7: WP4 | K7: =SUMIFS($A$13:$A$34,$C$13:$C$34,$J7) -> 0
A8: Organization | J8: WP5 | K8: =SUMIFS($A$13:$A$34,$C$13:$C$34,$J8) -> 0
A9: Staff category | J9: WP6 | K9: =SUMIFS($A$13:$A$34,$C$13:$C$34,$J9) -> 0
J10: WP7 | K10: =SUMIFS($A$13:$A$34,$C$13:$C$34,$J10) -> 0
A12: Total number of hours | B12: Day | C12: Work Package | D12: Comments
A35: =SUM(A13:A34) -> 0
B36: Date | G36: Signature of the staff member | L36: Signature of the person responsbile in the institution

Sheet June23
A2: Project name | C2: =Summary!B8 -> GREATER – Growing Rwanda Energy Awareness Through highER education | J2: Summary
J3: Work Package | K3: Hours
A4: Project ID | C4: =Summary!B9 -> 101083081 ERASMUS-EDU-2022-CBHE | J4: WP1 | K4: =SUMIFS($A$13:$A$34,$C$13:$C$34,$J4) -> 0
A5: Month | C5: June | J5: WP2 | K5: =SUMIFS($A$13:$A$34,$C$13:$C$34,$J5) -> 0
A6: Year | C6: 2023 | J6: WP3 | K6: =SUMIFS($A$13:$A$34,$C$13:$C$34,$J6) -> 0
A7: Employee | J7: WP4 | K7: =SUMIFS($A$13:$A$34,$C$13:$C$34,$J7) -> 0
A8: Organization | J8: WP5 | K8: =SUMIFS($A$13:$A$34,$C$13:$C$34,$J8) -> 0
A9: Staff category | J9: WP6 | K9: =SUMIFS($A$13:$A$34,$C$13:$C$34,$J9) -> 0
J10: WP7 | K10: =SUMIFS($A$13:$A$34,$C$13:$C$34,$J10) -> 0
A12: Total number of hours | B12: Day | C12: Work Package | D12: Comments
A35: =SUM(A13:A34) -> 0
B36: Date | G36: Signature of the staff member | L36: Signature of the person responsbile in the institution

Sheet July23
A2: Project name | C2: =Summary!B8 -> GREATER – Growing Rwanda Energy Awareness Through highER education | J2: Summary
J3: Work Package | K3: Hours
A4: Project ID | C4: =Summary!B9 -> 101083081 ERASMUS-EDU-2022-CBHE | J4: WP1 | K4: =SUMIFS($A$13:$A$34,$C$13:$C$34,$J4) -> 0
A5: Month | C5: July | J5: WP2 | K5: =SUMIFS($A$13:$A$34,$C$13:$C$34,$J5) -> 0
A6: Year | C6: 2023 | J6: WP3 | K6: =SUMIFS($A$13:$A$34,$C$13:$C$34,$J6) -> 0
A7: Employee | J7: WP4 | K7: =SUMIFS($A$13:$A$34,$C$13:$C$34,$J7) -> 0
A8: Organization | J8: WP5 | K8: =SUMIFS($A$13:$A$34,$C$13:$C$34,$J8) -> 0
A9: Staff category | J9: WP6 | K9: =SUMIFS($A$13:$A$34,$C$13:$C$34,$J9) -> 0
J10: WP7 | K10: =SUMIFS($A$13:$A$34,$C$13:$C$34,$J10) -> 0
A12: Total number of hours | B12: Day | C12: Work Package | D12: Comments
A35: =SUM(A13:A34) -> 0
B36: Date | G36: Signature of the staff member | L36: Signature of the person responsbile in the institution

Sheet August23
A2: Project name | C2: =Summary!B8 -> GREATER – Growing Rwanda Energy Awareness Through highER education | J2: Summary
J3: Work Package | K3: Hours
A4: Project ID | C4: =Summary!B9 -> 101083081 ERASMUS-EDU-2022-CBHE | J4: WP1 | K4: =SUMIFS($A$13:$A$34,$C$13:$C$34,$J4) -> 0
A5: Month | C5: August | J5: WP2 | K5: =SUMIFS($A$13:$A$34,$C$13:$C$34,$J5) -> 0
A6: Year | C6: 2023 | J6: WP3 | K6: =SUMIFS($A$13:$A$34,$C$13:$C$34,$J6) -> 0
A7: Employee | J7: WP4 | K7: =SUMIFS($A$13:$A$34,$C$13:$C$34,$J7) -> 0
A8: Organization | J8: WP5 | K8: =SUMIFS($A$13:$A$34,$C$13:$C$34,$J8) -> 0
A9: Staff category | J9: WP6 | K9: =SUMIFS($A$13:$A$34,$C$13:$C$34,$J9) -> 0
J10: WP7 | K10: =SUMIFS($A$13:$A$34,$C$13:$C$34,$J10) -> 0
A12: Total number of hours | B12: Day | C12: Work Package | D12: Comments
A35: =SUM(A13:A34) -> 0
B36: Date | G36: Signature of the staff member | L36: Signature of the person responsbile in the institution

Sheet September23
A2: Project name | C2: =Summary!B8 -> GREATER – Growing Rwanda Energy Awareness Through highER education | J2: Summary
J3: Work Package | K3: Hours
A4: Project ID | C4: =Summary!B9 -> 101083081 ERASMUS-EDU-2022-CBHE | J4: WP1 | K4: =SUMIFS($A$13:$A$34,$C$13:$C$34,$J4) -> 0
A5: Month | C5: September | J5: WP2 | K5: =SUMIFS($A$13:$A$34,$C$13:$C$34,$J5) -> 0
A6: Year | C6: 2023 | J6: WP3 | K6: =SUMIFS($A$13:$A$34,$C$13:$C$34,$J6) -> 0
A7: Employee | J7: WP4 | K7: =SUMIFS($A$13:$A$34,$C$13:$C$34,$J7) -> 0
A8: Organization | J8: WP5 | K8: =SUMIFS($A$13:$A$34,$C$13:$C$34,$J8) -> 0
A9: Staff category | J9: WP6 | K9: =SUMIFS($A$13:$A$34,$C$13:$C$34,$J9) -> 0
J10: WP7 | K10: =SUMIFS($A$13:$A$34,$C$13:$C$34,$J10) -> 0
A12: Total number of hours | B12: Day | C12: Work Package | D12: Comments
A35: =SUM(A13:A34) -> 0
B36: Date | G36: Signature of the staff member | L36: Signature of the person responsbile in the institution

Sheet October23
A2: Project name | C2: =Summary!B8 -> GREATER – Growing Rwanda Energy Awareness Through highER education | J2: Summary
J3: Work Package | K3: Hours
A4: Project ID | C4: =Summary!B9 -> 101083081 ERASMUS-EDU-2022-CBHE | J4: WP1 | K4: =SUMIFS($A$13:$A$34,$C$13:$C$34,$J4) -> 0
A5: Month | C5: October | J5: WP2 | K5: =SUMIFS($A$13:$A$34,$C$13:$C$34,$J5) -> 0
A6: Year | C6: 2023 | J6: WP3 | K6: =SUMIFS($A$13:$A$34,$C$13:$C$34,$J6) -> 0
A7: Employee | J7: WP4 | K7: =SUMIFS($A$13:$A$34,$C$13:$C$34,$J7) -> 0
A8: Organization | J8: WP5 | K8: =SUMIFS($A$13:$A$34,$C$13:$C$34,$J8) -> 0
A9: Staff category | J9: WP6 | K9: =SUMIFS($A$13:$A$34,$C$13:$C$34,$J9) -> 0
J10: WP7 | K10: =SUMIFS($A$13:$A$34,$C$13:$C$34,$J10) -> 0
A12: Total number of hours | B12: Day | C12: Work Package | D12: Comments
A35: =SUM(A13:A34) -> 0
B36: Date | G36: Signature of the staff member | L36: Signature of the person responsbile in the institution

Sheet November23
A2: Project name | C2: =Summary!B8 -> GREATER – Growing Rwanda Energy Awareness Through highER education | J2: Summary
J3: Work Package | K3: Hours
A4: Project ID | C4: =Summary!B9 -> 101083081 ERASMUS-EDU-2022-CBHE | J4: WP1 | K4: =SUMIFS($A$13:$A$34,$C$13:$C$34,$J4) -> 0
A5: Month | C5: November | J5: WP2 | K5: =SUMIFS($A$13:$A$34,$C$13:$C$34,$J5) -> 0
A6: Year | C6: 2023 | J6: WP3 | K6: =SUMIFS($A$13:$A$34,$C$13:$C$34,$J6) -> 0
A7: Employee | J7: WP4 | K7: =SUMIFS($A$13:$A$34,$C$13:$C$34,$J7) -> 0
A8: Organization | J8: WP5 | K8: =SUMIFS($A$13:$A$34,$C$13:$C$34,$J8) -> 0
A9: Staff category | J9: WP6 | K9: =SUMIFS($A$13:$A$34,$C$13:$C$34,$J9) -> 0
J10: WP7 | K10: =SUMIFS($A$13:$A$34,$C$13:$C$34,$J10) -> 0
A12: Total number of hours | B12: Day | C12: Work Package | D12: Comments
A35: =SUM(A13:A34) -> 0
B36: Date | G36: Signature of the staff member | L36: Signature of the person responsbile in the institution

Sheet December23
A2: Project name | C2: =Summary!B8 -> GREATER – Growing Rwanda Energy Awareness Through highER education | J2: Summary
J3: Work Package | K3: Hours
A4: Project ID | C4: =Summary!B9 -> 101083081 ERASMUS-EDU-2022-CBHE | J4: WP1 | K4: =SUMIFS($A$13:$A$34,$C$13:$C$34,$J4) -> 0
A5: Month | C5: December | J5: WP2 | K5: =SUMIFS($A$13:$A$34,$C$13:$C$34,$J5) -> 0
A6: Year | C6: 2023 | J6: WP3 | K6: =SUMIFS($A$13:$A$34,$C$13:$C$34,$J6) -> 0
A7: Employee | J7: WP4 | K7: =SUMIFS($A$13:$A$34,$C$13:$C$34,$J7) -> 0
A8: Organization | J8: WP5 | K8: =SUMIFS($A$13:$A$34,$C$13:$C$34,$J8) -> 0
A9: Staff category | J9: WP6 | K9: =SUMIFS($A$13:$A$34,$C$13:$C$34,$J9) -> 0
J10: WP7 | K10: =SUMIFS($A$13:$A$34,$C$13:$C$34,$J10) -> 0
A12: Total number of hours | B12: Day | C12: Work Package | D12: Comments
A35: =SUM(A13:A34) -> 0
B36: Date | G36: Signature of the staff member | L36: Signature of the person responsbile in the institution

Sheet January24
A2: Project name | C2: =Summary!B8 -> GREATER – Growing Rwanda Energy Awareness Through highER education | J2: Summary
J3: Work Package | K3: Hours
A4: Project ID | C4: =Summary!B9 -> 101083081 ERASMUS-EDU-2022-CBHE | J4: WP1 | K4: =SUMIFS($A$13:$A$34,$C$13:$C$34,$J4) -> 3
A5: Month | C5: January | J5: WP2 | K5: =SUMIFS($A$13:$A$34,$C$13:$C$34,$J5) -> 0
A6: Year | C6: 2024 | J6: WP3 | K6: =SUMIFS($A$13:$A$34,$C$13:$C$34,$J6) -> 0
A7: Employee | J7: WP4 | K7: =SUMIFS($A$13:$A$34,$C$13:$C$34,$J7) -> 0
A8: Organization | C8: UNIPR - UNIVERSITÀ DEGLI STUDI DI PARMA | J8: WP5 | K8: =SUMIFS($A$13:$A$34,$C$13:$C$34,$J8) -> 0
A9: Staff category | C9: Junior Lecturer / Research assistant | J9: WP6 | K9: =SUMIFS($A$13:$A$34,$C$13:$C$34,$J9) -> 0
J10: WP7 | K10: =SUMIFS($A$13:$A$34,$C$13:$C$34,$J10) -> 0
A12: Total number of hours | B12: Day | C12: Work Package | D12: Comments
A13: 3 | B13: 11 | C13: WP1
A35: =SUM(A13:A34) -> 3
B36: Date | G36: Signature of the staff member | L36: Signature of the person responsbile in the institution

Sheet February24
A2: Project name | C2: =Summary!B8 -> GREATER – Growing Rwanda Energy Awareness Through highER education | J2: Summary
J3: Work Package | K3: Hours
A4: Project ID | C4: =Summary!B9 -> 101083081 ERASMUS-EDU-2022-CBHE | J4: WP1 | K4: =SUMIFS($A$13:$A$34,$C$13:$C$34,$J4) -> 0
A5: Month | C5: February | J5: WP2 | K5: =SUMIFS($A$13:$A$34,$C$13:$C$34,$J5) -> 0
A6: Year | C6: 2024 | J6: WP3 | K6: =SUMIFS($A$13:$A$34,$C$13:$C$34,$J6) -> 0
A7: Employee | J7: WP4 | K7: =SUMIFS($A$13:$A$34,$C$13:$C$34,$J7) -> 0
A8: Organization | J8: WP5 | K8: =SUMIFS($A$13:$A$34,$C$13:$C$34,$J8) -> 0
A9: Staff category | J9: WP6 | K9: =SUMIFS($A$13:$A$34,$C$13:$C$34,$J9) -> 0
J10: WP7 | K10: =SUMIFS($A$13:$A$34,$C$13:$C$34,$J10) -> 0
A12: Total number of hours | B12: Day | C12: Work Package | D12: Comments
A35: =SUM(A13:A34) -> 0
B36: Date | G36: Signature of the staff member | L36: Signature of the person responsbile in the institution

Sheet March24
A2: Project name | C2: =Summary!B8 -> GREATER – Growing Rwanda Energy Awareness Through highER education | J2: Summary
J3: Work Package | K3: Hours
A4: Project ID | C4: =Summary!B9 -> 101083081 ERASMUS-EDU-2022-CBHE | J4: WP1 | K4: =SUMIFS($A$13:$A$34,$C$13:$C$34,$J4) -> 0
A5: Month | C5: March | J5: WP2 | K5: =SUMIFS($A$13:$A$34,$C$13:$C$34,$J5) -> 0
A6: Year | C6: 2024 | J6: WP3 | K6: =SUMIFS($A$13:$A$34,$C$13:$C$34,$J6) -> 0
A7: Employee | J7: WP4 | K7: =SUMIFS($A$13:$A$34,$C$13:$C$34,$J7) -> 0
A8: Organization | J8: WP5 | K8: =SUMIFS($A$13:$A$34,$C$13:$C$34,$J8) -> 0
A9: Staff category | J9: WP6 | K9: =SUMIFS($A$13:$A$34,$C$13:$C$34,$J9) -> 0
J10: WP7 | K10: =SUMIFS($A$13:$A$34,$C$13:$C$34,$J10) -> 0
A12: Total number of hours | B12: Day | C12: Work Package | D12: Comments
A35: =SUM(A13:A34) -> 0
B36: Date | G36: Signature of the staff member | L36: Signature of the person responsbile in the institution

Sheet April24
A2: Project name | C2: =Summary!B8 -> GREATER – Growing Rwanda Energy Awareness Through highER education | J2: Summary
J3: Work Package | K3: Hours
A4: Project ID | C4: =Summary!B9 -> 101083081 ERASMUS-EDU-2022-CBHE | J4: WP1 | K4: =SUMIFS($A$13:$A$34,$C$13:$C$34,$J4) -> 0
A5: Month | C5: April | J5: WP2 | K5: =SUMIFS($A$13:$A$34,$C$13:$C$34,$J5) -> 0
A6: Year | C6: 2024 | J6: WP3 | K6: =SUMIFS($A$13:$A$34,$C$13:$C$34,$J6) -> 0
A7: Employee | J7: WP4 | K7: =SUMIFS($A$13:$A$34,$C$13:$C$34,$J7) -> 0
A8: Organization | J8: WP5 | K8: =SUMIFS($A$13:$A$34,$C$13:$C$34,$J8) -> 0
A9: Staff category | J9: WP6 | K9: =SUMIFS($A$13:$A$34,$C$13:$C$34,$J9) -> 0
J10: WP7 | K10: =SUMIFS($A$13:$A$34,$C$13:$C$34,$J10) -> 0
A12: Total number of hours | B12: Day | C12: Work Package | D12: Comments
A35: =SUM(A13:A34) -> 0
B36: Date | G36: Signature of the staff member | L36: Signature of the person responsbile in the institution

Sheet May24
A2: Project name | C2: =Summary!B8 -> GREATER – Growing Rwanda Energy Awareness Through highER education | J2: Summary
J3: Work Package | K3: Hours
A4: Project ID | C4: =Summary!B9 -> 101083081 ERASMUS-EDU-2022-CBHE | J4: WP1 | K4: =SUMIFS($A$13:$A$34,$C$13:$C$34,$J4) -> 0
A5: Month | C5: April | J5: WP2 | K5: =SUMIFS($A$13:$A$34,$C$13:$C$34,$J5) -> 0
A6: Year | C6: 2024 | J6: WP3 | K6: =SUMIFS($A$13:$A$34,$C$13:$C$34,$J6) -> 0
A7: Employee | J7: WP4 | K7: =SUMIFS($A$13:$A$34,$C$13:$C$34,$J7) -> 0
A8: Organization | J8: WP5 | K8: =SUMIFS($A$13:$A$34,$C$13:$C$34,$J8) -> 0
A9: Staff category | J9: WP6 | K9: =SUMIFS($A$13:$A$34,$C$13:$C$34,$J9) -> 0
J10: WP7 | K10: =SUMIFS($A$13:$A$34,$C$13:$C$34,$J10) -> 0
A12: Total number of hours | B12: Day | C12: Work Package | D12: Comments
A35: =SUM(A13:A34) -> 0
B36: Date | G36: Signature of the staff member | L36: Signature of the person responsbile in the institution

Sheet June24
A2: Project name | C2: =Summary!B8 -> GREATER – Growing Rwanda Energy Awareness Through highER education | J2: Summary
J3: Work Package | K3: Hours
A4: Project ID | C4: =Summary!B9 -> 101083081 ERASMUS-EDU-2022-CBHE | J4: WP1 | K4: =SUMIFS($A$13:$A$34,$C$13:$C$34,$J4) -> 0
A5: Month | C5: April | J5: WP2 | K5: =SUMIFS($A$13:$A$34,$C$13:$C$34,$J5) -> 0
A6: Year | C6: 2024 | J6: WP3 | K6: =SUMIFS($A$13:$A$34,$C$13:$C$34,$J6) -> 0
A7: Employee | J7: WP4 | K7: =SUMIFS($A$13:$A$34,$C$13:$C$34,$J7) -> 0
A8: Organization | J8: WP5 | K8: =SUMIFS($A$13:$A$34,$C$13:$C$34,$J8) -> 0
A9: Staff category | J9: WP6 | K9: =SUMIFS($A$13:$A$34,$C$13:$C$34,$J9) -> 0
J10: WP7 | K10: =SUMIFS($A$13:$A$34,$C$13:$C$34,$J10) -> 0
A12: Total number of hours | B12: Day | C12: Work Package | D12: Comments
A35: =SUM(A13:A34) -> 0
B36: Date | G36: Signature of the staff member | L36: Signature of the person responsbile in the institution

Sheet Drop-down lists
F1: Days
F3: 1
F4: 2
F5: 3
D6: Work Package | F6: 4 | H6: Months | J6: Year | L6: Category of staff
D7: WP1 - Management and coordination | F7: 5 | L7: Senior Lecturer / Professor
D8: WP2 - Collaboration design | F8: 6 | H8: January | J8: 2023 | L8: Junior Lecturer / Research assistant
D9: WP3 - Infrastructures | F9: 7 | H9: February | J9: 2024 | L9: Technician
D10: WP4 - Curricula design | F10: 8 | H10: March | J10: 2025 | L10: Administrative
D11: WP5 - Training and coaching | F11: 9 | H11: April | L11: Other
D12: WP6 - Transfer methodologies | F12: 10 | H12: May
D13: WP7 - Impact and dissemination | F13: 11 | H13: June
F14: 12 | H14: July
F15: 13 | H15: August
F16: 14 | H16: September
F17: 15 | H17: October
F18: 16 | H18: November
F19: 17 | H19: December
D20: Number of hrs per working day | F20: 18
D21: 8 | F21: 19
F22: 20
F23: 21
F24: 22 | L24: Organization
F25: 23 | L25: UNIPR - UNIVERSITÀ DEGLI STUDI DI PARMA
F26: 24 | L26: HN - HOCHSCHULE NIEDERRHEIN,
F27: 25 | L27: HBRS - HOCHSCHULE BONN-RHEIN-SIEG,
F28: 26 | L28: UR - UNIVERSITY OF RWANDA,
F29: 27 | L29: RP - RWANDA POLYTECHNIC
F30: 28 | L30: INES - INSTITUT D'ENSEIGNEMENT SUPERIEUR DE RUHENGERI,
F31: 29 | L31: UTAB - UNIVERSITY OF TECHNOLOGY AND ARTS OF BYUMBA,
F32: 30 | L32: IMEM - CONSIGLIO NAZIONALE DELLE RICERCHE-IMEM,
F33: 31
